Workbook

Sheet Invoice_141787_2026-06-30
A1: Invoice Number | B1: Date | C1: Item Id | D1: Short Description | E1: Description | F1: Amount | G1: Product Id | H1: Group Name | I1: Service Type | J1: Customer Name | K1: Customer Reference | L1: Service Item | M1: Service Item Uuid | N1: IP Address | O1: ASID | P1: Service Order | Q1: Product | R1: Contract Term | S1: Ratecard | T1: Product Name | U1: Quantity | V1: Start Date | W1: End Date | X1: Service Inception | Y1: External Reference | Z1: Username | AA1: Contact Name
A2: 141787 | B2: 46203 | C2: 6458601 | D2: 64508247253 | E2: Toll Free Number - 0508 247253 (01/07/2026 - 31/07/2026) | F2: 0 | G2: 470 | H2: VoIP | I2: Voice | J2: Circle IT | K2: 700188 | L2: 0508247253 | M2: fb04457a-1eba-5579-9f29-4d56bb5523fa | P2: 8662 | Q2: Toll Free Number | S2: 0800_rates_wholesale_Net7 | T2: Toll Free Number | U2: 1 | V2: 46204 | W2: 46234 | X2: 43089 | Z2: 0508247253 | AA2: Circle IT
A3: 141787 | B3: 46203 | C3: 6468327 | D3: 64800101510 | E3: Toll Free Number - 0800 101510 (01/07/2026 - 31/07/2026) | F3: 0 | G3: 470 | H3: VoIP | I3: Voice | J3: Leukaemia Foundation | K3: 700188 | L3: 0800101510 | M3: 81c7a92e-448b-5c49-bd24-f531227b18c9 | P3: 19140 | Q3: Toll Free Number | S3: 0800_rates_wholesale_Net7 | T3: Toll Free Number | U3: 1 | V3: 46204 | W3: 46234 | X3: 44033 | Z3: 0800101510 | AA3: Darren Wong
A4: 141787 | B4: 46203 | C4: 6468404 | D4: 64800151015 | E4: Toll Free Number - 0800 151015 (01/07/2026 - 31/07/2026) | F4: 0 | G4: 470 | H4: VoIP | I4: Voice | J4: Leukaemia Foundation | K4: 700188 | L4: 0800151015 | M4: f98b5da8-9b3a-5313-bb99-936c536aa4b4 | P4: 19141 | Q4: Toll Free Number | S4: 0800_rates_wholesale_Net7 | T4: Toll Free Number | U4: 1 | V4: 46204 | W4: 46234 | X4: 44033 | Z4: 0800151015 | AA4: Darren Wong
A5: 141787 | B5: 46203 | C5: 6473475 | D5: 6492555213 | E5: Fax 2 Email - 09 2555213 (01/07/2026 - 31/07/2026) | F5: 6 | G5: 40 | H5: VoIP | I5: Voice | J5: Iosis Ltd | K5: 700188 | L5: 6492555213 | M5: e314250c-283a-5359-bd2f-d9d19a56584f | P5: 16534 | Q5: Fax 2 Email | S5: rate_wholesale_Net7 | T5: Fax 2 Email | U5: 1 | V5: 46204 | W5: 46234 | X5: 44195 | Z5: 6492555213 | AA5: Darren Wong
A6: 141787 | B6: 46203 | C6: 6473703 | D6: 6492679431 | E6: Fax 2 Email - 09 2679431 (01/07/2026 - 31/07/2026) | F6: 6 | G6: 40 | H6: VoIP | I6: Voice | J6: Iosis Ltd | K6: 700188 | L6: 6492679431 | M6: d9f35d1d-7884-5cf0-a95a-829142bcc801 | P6: 16533 | Q6: Fax 2 Email | S6: rate_wholesale_Net7 | T6: Fax 2 Email | U6: 1 | V6: 46204 | W6: 46234 | X6: 44033 | Z6: 6492679431 | AA6: Darren Wong
A7: 141787 | B7: 46203 | C7: 6478034 | D7: 6495216507 | E7: Fax 2 Email - 09 5216507 (01/07/2026 - 31/07/2026) | F7: 6 | G7: 40 | H7: VoIP | I7: Voice | J7: Quinn Law | K7: 12345 | L7: 6495216507 | M7: bfcf9e01-76b9-54a2-b451-8eb3de3c39f0 | P7: 52984 | Q7: Fax 2 Email | S7: rate_wholesale_Net7 | T7: Fax 2 Email | U7: 1 | V7: 46204 | W7: 46234 | X7: 44295 | Z7: 6495216507 | AA7: Darren Wong
A8: 141787 | B8: 46203 | C8: 6479886 | D8: 6496383557 | E8: Fax 2 Email - 09 6383557 (01/07/2026 - 31/07/2026) | F8: 6 | G8: 40 | H8: VoIP | I8: Voice | J8: Leukaemia Foundation | K8: 700188 | L8: 6496383557 | M8: 96ebd12c-04ff-5d1f-b324-0111bdac5d77 | P8: 19023 | Q8: Fax 2 Email | S8: rate_wholesale_Net7 | T8: Fax 2 Email | U8: 1 | V8: 46204 | W8: 46234 | X8: 44033 | Z8: 6496383557 | AA8: Darren Wong
A9: 141787 | B9: 46203 | C9: 6486366 | D9: 1636501970 | E9: UFB - Small Business Fibre 500 - 1636501970 (Order: 107254980) (01/07/2026 - 31/07/2026) Contract Term: Casual | F9: 87 | G9: 397 | H9: Chorus UFB | I9: Service Order | J9: Circle IT | K9: Circle IT - 34 Jervois Road | L9: 1636501970 | M9: 7516017c-5d57-5761-b299-a28cd8b22a10 | N9: 14.1.46.69 | O9: 1636501970 | P9: 2000942227 | Q9: UFB - Small Business Fibre 500 | R9: casual | T9: UFB - Small Business Fibre 500 | U9: 1 | V9: 46204 | W9: 46234 | X9: 45033 | Z9: circle-office@circlenet.co.nz | AA9: Circle IT
A10: 141787 | B10: 46203 | C10: 6486394 | D10: 1636548917 | E10: UFB - Home Fibre 920 - 1636548917 (Order: 101397116) (01/07/2026 - 31/07/2026) Contract Term: 24 Month Term | F10: 95 | G10: 243 | H10: Chorus UFB | I10: Service Order | J10: Rebecca Wong | K10: Rebecca Wong - 90 Bramley Drive | L10: 1636548917 | M10: 54f1331d-6351-52b6-8254-16a499bbe6e6 | N10: 14.1.46.90 | O10: 1636548917 | P10: 87606 | Q10: UFB - Home Fibre 920 | R10: 24 months | T10: UFB - Home Fibre 920 | U10: 1 | V10: 46204 | W10: 46234 | X10: 43116 | Z10: circle-bramley@circlenet.co.nz | AA10: Rebecca Wong
A11: 141787 | B11: 46203 | C11: 6486971 | D11: 1637725796 | E11: UFB - Small Business Fibre 500 - 1637725796 (Order: 107255133) (01/07/2026 - 31/07/2026) Contract Term: Casual | F11: 87 | G11: 397 | H11: Chorus UFB | I11: Service Order | J11: Prodesigners | K11: Prodesigners - 10 Aylesbury Street | L11: 1637725796 | M11: 01eabfb3-5a6d-517f-9e7b-19ae9dc04c40 | N11: 14.1.46.68 | O11: 1637725796 | P11: 2000942270 | Q11: UFB - Small Business Fibre 500 | R11: casual | T11: UFB - Small Business Fibre 500 | U11: 1 | V11: 46204 | W11: 46234 | X11: 45033 | Z11: prodesigners@circlenet.co.nz | AA11: Prodesigners
A12: 141787 | B12: 46203 | C12: 6487069 | D12: 1638076641 | E12: UFB - Small Business Fibre 920 - 1638076641 (Order: 104896918) (01/07/2026 - 31/07/2026) Contract Term: 24 Month Term | F12: 100 | G12: 396 | H12: Chorus UFB | I12: Service Order | J12: Renegade Fitness | K12: Renegade Fitness - 5 Nandina Avenue | L12: 1638076641 | M12: 66d5c62a-1a36-5cd3-8284-d12b937c815a | N12: 14.1.46.72 | O12: 1638076641 | P12: 378007 | Q12: UFB - Small Business Fibre 920 | R12: 24 months | T12: UFB - Small Business Fibre 920 | U12: 1 | V12: 46204 | W12: 46234 | X12: 44285 | Z12: ffet@circlenet.co.nz | AA12: Renegade Fitness
A13: 141787 | B13: 46203 | C13: 6487187 | D13: 1638228123 | E13: UFB - Small Business Fibre 920 - 1638228123 (Order: 105322520) (01/07/2026 - 31/07/2026) Contract Term: 24 Month Term | F13: 100 | G13: 396 | H13: Chorus UFB | I13: Service Order | J13: Western Engineering | K13: Western Engineering - 11 Patiki Road | L13: 1638228123 | M13: 5824471f-6624-5f84-979b-43a54adc118f | N13: 14.1.46.64 | O13: 1638228123 | P13: 2000490494 | Q13: UFB - Small Business Fibre 920 | R13: 24 months | T13: UFB - Small Business Fibre 920 | U13: 1 | V13: 46204 | W13: 46234 | X13: 44398 | Z13: western@circlenet.co.nz | AA13: Western Engineering
A14: 141787 | B14: 46203 | C14: 6487236 | D14: 1638300107 | E14: UFB - Small Business Fibre 920 - 1638300107 (Order: 105520616) (01/07/2026 - 31/07/2026) Contract Term: 24 Month Term | F14: 100 | G14: 396 | H14: Chorus UFB | I14: Service Order | J14: Darren Wong | K14: Darren Wong - 4 Ambedkar Way | L14: 1638300107 | M14: 8b89f54b-3242-58f8-a127-8e84e15956a9 | N14: 14.1.46.65 | O14: 1638300107 | P14: 2000535808 | Q14: UFB - Small Business Fibre 920 | R14: 24 months | T14: UFB - Small Business Fibre 920 | U14: 1 | V14: 46204 | W14: 46234 | X14: 44476 | Z14: darren@circlenet.co.nz | AA14: Darren Wong
A15: 141787 | B15: 46203 | C15: 6487316 | D15: 1638396111 | E15: UFB - Home Fibre 920 - 1638396111 (Order: 105786570) (01/07/2026 - 31/07/2026) Contract Term: 24 Month Term | F15: 95 | G15: 243 | H15: Chorus UFB | I15: Service Order | J15: Ryan Ouston | K15: Ryan Ouston - 5 Kaihuia Lane | L15: 1638396111 | M15: 2340321d-4004-5511-88c5-8f18fe7ef263 | N15: 14.1.46.79 | O15: 1638396111 | P15: 2000589930 | Q15: UFB - Home Fibre 920 | R15: 24 months | T15: UFB - Home Fibre 920 | U15: 1 | V15: 46204 | W15: 46234 | X15: 44568 | Z15: cryry@circlenet.co.nz | AA15: Ryan Ouston
A16: 141787 | B16: 46203 | C16: 6487352 | D16: 1638453738 | E16: UFB - Small Business Fibre 920 - 1638453738 (Order: 109171633) (01/07/2026 - 31/07/2026) Contract Term: 24 Month Term | F16: 100 | G16: 396 | H16: Chorus UFB | I16: Service Order | J16: Mag and Turbo Pukekohe | K16: M&T Pukekohe - 123 Manukau Road | L16: 1638453738 | M16: 71f0f5c3-2f88-55da-99fc-86f629544dbb | N16: 14.1.46.81 | O16: 1638453738 | P16: 2000626936 | Q16: UFB - Small Business Fibre 920 | R16: 24 months | T16: UFB - Small Business Fibre 920 | U16: 1 | V16: 46204 | W16: 46234 | X16: 44605 | Z16: mag_pukekohe@circlenet.co.nz | AA16: Mag and Turbo Pukekohe
A17: 141787 | B17: 46203 | C17: 6487612 | D17: 1638724911 | E17: UFB - Small Business Fibre 500 - 1638724911 (Order: 106657214) (01/07/2026 - 31/07/2026) Contract Term: Casual | F17: 87 | G17: 397 | H17: Chorus UFB | I17: Service Order | J17: Puffing Kiwi - 216 Great South Road | K17: Puffing Kiwi - 216 Great South Road | L17: 1638724911 | M17: 6a34249c-e3f1-5666-bf75-08291dae25cc | N17: 202.74.200.37 | O17: 1638724911 | P17: 2000801093 | Q17: UFB - Small Business Fibre 500 | R17: 12 months | T17: UFB - Small Business Fibre 500 | U17: 1 | V17: 46204 | W17: 46234 | X17: 44845 | Z17: NO LOGIN | AA17: Puffing Kiwi - 216 Great South Road
A18: 141787 | B18: 46203 | C18: 6487613 | D18: 1638724911 | E18: Static IP - 1638724911 - 202.74.200.37 (01/07/2026 - 31/07/2026) | F18: 5 | G18: 474 | H18: Unlimited Data | I18: Fixed Wireless | J18: Puffing Kiwi - 216 Great South Road | K18: Puffing Kiwi - 216 Great South Road | L18: 1638724911 | M18: 6a34249c-e3f1-5666-bf75-08291dae25cc | N18: 202.74.200.37 | O18: 1638724911 | P18: 2000801093 | Q18: Static IP | R18: 12 months | T18: Static IP | U18: 1 | V18: 46204 | W18: 46234 | X18: 44845 | Z18: NO LOGIN | AA18: Puffing Kiwi - 216 Great South Road
A19: 141787 | B19: 46203 | C19: 6487647 | D19: 1638752055 | E19: UFB - Small Business Fibre 500 - 1638752055 (Order: 106720907) (01/07/2026 - 31/07/2026) Contract Term: Casual | F19: 87 | G19: 397 | H19: Chorus UFB | I19: Service Order | J19: Catch of the Day | K19: Puffing Kiwi - 274 Penrose Road | L19: 1638752055 | M19: 61ac1f4e-e489-5ff2-bca2-9343c56847f1 | N19: 202.74.200.39 | O19: 1638752055 | P19: 2000803067 | Q19: UFB - Small Business Fibre 500 | R19: 12 months | T19: UFB - Small Business Fibre 500 | U19: 1 | V19: 46204 | W19: 46234 | X19: 44851 | Z19: NO LOGIN | AA19: Catch of the Day
A20: 141787 | B20: 46203 | C20: 6487648 | D20: 1638752055 | E20: Static IP - 1638752055 - 202.74.200.39 (01/07/2026 - 31/07/2026) | F20: 5 | G20: 474 | H20: Unlimited Data | I20: Fixed Wireless | J20: Catch of the Day | K20: Puffing Kiwi - 274 Penrose Road | L20: 1638752055 | M20: 61ac1f4e-e489-5ff2-bca2-9343c56847f1 | N20: 202.74.200.39 | O20: 1638752055 | P20: 2000803067 | Q20: Static IP | R20: 12 months | T20: Static IP | U20: 1 | V20: 46204 | W20: 46234 | X20: 44851 | Z20: NO LOGIN | AA20: Catch of the Day
... A25: 141787 | B25: 46203 | C25: 6488759 | D25: 1639450980 | E25: UFB - Small Business Fibre 920 - 1639450980 (Order: 108247950) (01/07/2026 - 31/07/2026) Contract Term: Casual | F25: 100 | G25: 396 | H25: Chorus UFB | I25: Service Order | J25: Asphaltech | K25: Asphaltech - 30A Parkway Drive | L25: 1639450980 | M25: d72ec97e-2d25-5490-ba3c-b889f6cdd9b5 | N25: 14.1.46.86 | O25: 1639450980 | P25: 2001191499 | Q25: UFB - Small Business Fibre 920 | R25: 12 months | T25: UFB - Small Business Fibre 920 | U25: 1 | V25: 46204 | W25: 46234 | X25: 45372 | Z25: asphaltech@circlenet.co.nz | AA25: Asphaltech
A26: 141787 | B26: 46203 | C26: 6489120 | D26: 1639613220 | E26: UFB - Small Business Fibre 500 - 1639613220 (Order: 108664632) (01/07/2026 - 31/07/2026) Contract Term: Casual | F26: 87 | G26: 397 | H26: Chorus UFB | I26: Service Order | J26: Mapfc - 19A Preston Avenue | K26: Mapfc - 19A Preston Avenue | L26: 1639613220 | M26: 8b2f5375-e11c-55ba-ab96-65cbef28fea9 | O26: 1639613220 | P26: 2001320778 | Q26: UFB - Small Business Fibre 500 | R26: casual | T26: UFB - Small Business Fibre 500 | U26: 1 | V26: 46204 | W26: 46234 | X26: 45623 | Z26: NO LOGIN | AA26: Mapfc - 19A Preston Avenue
A27: 141787 | B27: 46203 | C27: 6489398 | D27: 1639698438 | E27: UFB - Small Business Fibre 920 - 1639698438 (Order: 108893147) (01/07/2026 - 31/07/2026) Contract Term: 24 Month Term | F27: 100 | G27: 396 | H27: Chorus UFB | I27: Service Order | J27: Nauru Program Office NZ | K27: Nauru - LVL 15, 191 Queen Street | L27: 1639698438 | M27: 6ebc07c1-1eb2-50d0-aff8-5d713e586d57 | N27: 14.1.46.87 | O27: 1639698438 | P27: 2001406124 | Q27: UFB - Small Business Fibre 920 | R27: 24 months | T27: UFB - Small Business Fibre 920 | U27: 1 | V27: 46204 | W27: 46234 | X27: 45590 | Z27: nauru@circlenet.co.nz | AA27: Nauru Program Office NZ
A28: 141787 | B28: 46203 | C28: 6489512 | D28: 1639736674 | E28: UFB - Small Business Fibre 920 - 1639736674 (Order: 108996305) (01/07/2026 - 31/07/2026) Contract Term: Casual | F28: 100 | G28: 396 | H28: Chorus UFB | I28: Service Order | J28: Quinn Law | K28: Quinn Law - 78 Coates Avenue | L28: 1639736674 | M28: 9b4afeaa-0590-5575-9845-c4b88dcbb19d | N28: 14.1.46.70 | O28: 1639736674 | P28: 2001436297 | Q28: UFB - Small Business Fibre 920 | R28: casual | T28: UFB - Small Business Fibre 920 | U28: 1 | V28: 46204 | W28: 46234 | X28: 45631 | Z28: quinnlaw@circlenet.co.nz | AA28: Quinn Law
A29: 141787 | B29: 46203 | C29: 6489991 | D29: 1639902626 | E29: UFB - Small Business Fibre 920 - 1639902626 (Order: 109511445) (01/07/2026 - 31/07/2026) Contract Term: Casual | F29: 100 | G29: 396 | H29: Chorus UFB | I29: Service Order | J29: Iosis Ltd | K29: Iosis - 112C Russel Road | L29: 1639902626 | M29: f2ace68a-804e-5e32-8273-48167dbe4af7 | N29: 202.74.204.68 | O29: 1639902626 | P29: 2001592725 | Q29: UFB - Small Business Fibre 920 | R29: 12 months | T29: UFB - Small Business Fibre 920 | U29: 1 | V29: 46204 | W29: 46234 | X29: 45785 | Z29: NO LOGIN | AA29: Iosis Ltd
A30: 141787 | B30: 46203 | C30: 6489992 | D30: 1639902626 | E30: Static IP - 1639902626 - 202.74.204.68 (01/07/2026 - 31/07/2026) | F30: 5 | G30: 474 | H30: Unlimited Data | I30: Fixed Wireless | J30: Iosis Ltd | K30: Iosis - 112C Russel Road | L30: 1639902626 | M30: f2ace68a-804e-5e32-8273-48167dbe4af7 | N30: 202.74.204.68 | O30: 1639902626 | P30: 2001592725 | Q30: Static IP | R30: 12 months | T30: Static IP | U30: 1 | V30: 46204 | W30: 46234 | X30: 45785 | Z30: NO LOGIN | AA30: Iosis Ltd
A31: 141787 | B31: 46203 | C31: 6490740 | D31: 1643157786 | E31: UFB - Small Business Fibre 920 - 1643157786 (Order: 110182714) (01/07/2026 - 31/07/2026) Contract Term: Casual | F31: 100 | G31: 396 | H31: Chorus UFB | I31: Service Order | J31: Alaska AKL - 4 Murdoch Road | K31: Alaska AKL - 4 Murdoch Road | L31: 1643157786 | M31: 781fb416-131f-56fd-a907-3c47251507e1 | N31: 202.74.205.217 | O31: 1643157786 | P31: 2001770135 | Q31: UFB - Small Business Fibre 920 | R31: casual | T31: UFB - Small Business Fibre 920 | U31: 1 | V31: 46204 | W31: 46234 | X31: 45975 | Z31: NO LOGIN | AA31: Alaska AKL - 4 Murdoch Road
A32: 141787 | B32: 46203 | C32: 6490741 | D32: 1643157786 | E32: Static IP - 1643157786 - 202.74.205.217 (01/07/2026 - 31/07/2026) | F32: 5 | G32: 474 | H32: Unlimited Data | I32: Fixed Wireless | J32: Alaska AKL - 4 Murdoch Road | K32: Alaska AKL - 4 Murdoch Road | L32: 1643157786 | M32: 781fb416-131f-56fd-a907-3c47251507e1 | N32: 202.74.205.217 | O32: 1643157786 | P32: 2001770135 | Q32: Static IP | R32: casual | T32: Static IP | U32: 1 | V32: 46204 | W32: 46234 | X32: 45975 | Z32: NO LOGIN | AA32: Alaska AKL - 4 Murdoch Road
A33: 141787 | B33: 46203 | C33: 6490744 | D33: 1643159145 | E33: UFB - Small Business Fibre 920 - 1643159145 (Order: 110186381) (01/07/2026 - 31/07/2026) Contract Term: Casual | F33: 100 | G33: 396 | H33: Chorus UFB | I33: Service Order | J33: Alaska WLG - 1/15 Glover Street | K33: Alaska WLG - 1/15 Glover Street | L33: 1643159145 | M33: 45bced54-d53a-5901-a087-0dfa149935bd | N33: 202.74.205.225 | O33: 1643159145 | P33: 2001771161 | Q33: UFB - Small Business Fibre 920 | R33: casual | T33: UFB - Small Business Fibre 920 | U33: 1 | V33: 46204 | W33: 46234 | X33: 45978 | Z33: NO LOGIN | AA33: Alaska WLG - 1/15 Glover Street
A34: 141787 | B34: 46203 | C34: 6490745 | D34: 1643159145 | E34: Static IP - 1643159145 - 202.74.205.225 (01/07/2026 - 31/07/2026) | F34: 5 | G34: 474 | H34: Unlimited Data | I34: Fixed Wireless | J34: Alaska WLG - 1/15 Glover Street | K34: Alaska WLG - 1/15 Glover Street | L34: 1643159145 | M34: 45bced54-d53a-5901-a087-0dfa149935bd | N34: 202.74.205.225 | O34: 1643159145 | P34: 2001771161 | Q34: Static IP | R34: casual | T34: Static IP | U34: 1 | V34: 46204 | W34: 46234 | X34: 45978 | Z34: NO LOGIN | AA34: Alaska WLG - 1/15 Glover Street
A35: 141787 | B35: 46203 | C35: 6491697 | D35: 1694062640 | E35: VDSL Broadband - 1694062640 (OOT: 61472681) (01/07/2026 - 31/07/2026) Data Allowance: Custom Data Plan Contract Term: 24 Month Term ASID: | F35: 79.5 | G35: 124 | H35: Broadband | I35: Service Order | J35: NZ Cucumbers | K35: NZ Cucumbers - 353 Harrisville Road | L35: 1694062640 | M35: f3423416-c02b-5e93-ba10-f281e7adc504 | N35: 14.1.46.74 | O35: 1694062640 | P35: 100845 | Q35: VDSL Broadband | R35: 24 months | T35: VDSL Broadband | U35: 1 | V35: 46204 | W35: 46234 | X35: 43341 | Z35: passionfresh@circlenet.co.nz | AA35: Ben Winkelaar
A36: 141787 | B36: 46203 | C36: 6491799 | D36: 611800464093 | E36: Australia Toll Free Number - 1800 464093 (01/07/2026 - 31/07/2026) | F36: 16 | G36: 471 | H36: International VoIP | I36: Voice | J36: Unknown | L36: 611800464093 | P36: 0 | Q36: Australia Toll Free Number | T36: Australia Toll Free Number | U36: 1 | V36: 46204 | W36: 46234 | X36: 0000-00-00
A37: 141787 | B37: 46203 | C37: 6497933 | D37: 14.1.57.240 | E37: Cross Connect - Data Vault Co-location 200/200 connection and Static IP 14.1.57.240/29 (01/07/2026 - 31/07/2026) | F37: 171.2 | G37: 37 | H37: Hosting and Colocation | I37: Misc | J37: Unknown | L37: 14.1.57.240 | P37: 0 | Q37: Cross Connect | T37: Cross Connect | U37: 1 | V37: 46204 | W37: 46234 | X37: 0000-00-00
A38: 141787 | B38: 46203 | C38: 6498554 | D38: ENVIBB02616560 | E38: UFB - SME Fibre Max - ENVIBB02616560 (Order: 1236045) (01/07/2026 - 31/07/2026) Contract Term: Casual | F38: 110.5 | G38: 366 | H38: Enable UFB | I38: Service Order | J38: Alaska CHCH - Unit 5/9 Sir Gil Simpson Dr | K38: Alaska CHCH - Unit 5/9 Sir Gil Simpson Dr | L38: ENVIBB02616560 | M38: 5f3f5686-8f98-5d75-bd47-0bedb4f65e3a | N38: 202.74.205.236 | O38: ENVIBB02616560 | P38: 2001771563 | Q38: UFB - SME Fibre Max | R38: casual | T38: UFB - SME Fibre Max | U38: 1 | V38: 46204 | W38: 46234 | X38: 45979 | Z38: NO LOGIN | AA38: Damain Brook
A39: 141787 | B39: 46203 | C39: 6498555 | D39: ENVIBB02616560 - 202.74.205.236 (01/07/2026 - 31/07/2026) | E39: Static IP - ENVIBB02616560 - 202.74.205.236 (01/07/2026 - 31/07/2026) | F39: 5 | G39: 474 | H39: Unlimited Data | I39: Fixed Wireless | J39: Alaska CHCH - Unit 5/9 Sir Gil Simpson Dr | L39: ENVIBB02616560 - 202.74.205.236 (01/07/2026 - 31/07/2026) | P39: 0 | Q39: Static IP | T39: Static IP | U39: 1 | V39: 46204 | W39: 46234 | X39: 0000-00-00
A40: 141787 | B40: 46203 | C40: 6500702 | D40: UFF000006981258 | E40: UFB - SME Fibre Max - UFF000006981258 (Order: 25134680) (01/07/2026 - 31/07/2026) Contract Term: Casual | F40: 118.5 | G40: 324 | H40: Ultrafast UFB | I40: Service Order | J40: Alaska TRG - 84 First Avenue | K40: Alaska TRG - 84 First Avenue | L40: UFF000006981258 | M40: 065a90e1-d473-5b72-8271-5dc5f36cfec1 | N40: 202.74.205.226 | O40: UFF000006981258 | P40: 2001771183 | Q40: UFB - SME Fibre Max | R40: casual | T40: UFB - SME Fibre Max | U40: 1 | V40: 46204 | W40: 46234 | X40: 45978 | Z40: NO LOGIN | AA40: Liam Osborne
A41: 141787 | B41: 46203 | C41: 6500703 | D41: UFF000006981258 - 202.74.205.226 (01/07/2026 - 31/07/2026) | E41: Static IP - UFF000006981258 - 202.74.205.226 (01/07/2026 - 31/07/2026) | F41: 5 | G41: 474 | H41: Unlimited Data | I41: Fixed Wireless | J41: Alaska TRG - 84 First Avenue | L41: UFF000006981258 - 202.74.205.226 (01/07/2026 - 31/07/2026) | P41: 0 | Q41: Static IP | T41: Static IP | U41: 1 | V41: 46204 | W41: 46234 | X41: 0000-00-00
A42: 141787 | B42: 46203 | C42: 6500813 | D42: UFF000007273335 | E42: UFB - SME Fibre 300 - UFF000007273335 (Order: 25758564) (01/07/2026 - 31/07/2026) Contract Term: Casual | F42: 94.5 | G42: 184 | H42: Ultrafast UFB | I42: Service Order | J42: Sports Orthopaedic Surgery Centre | K42: Sportsortho - 162 Powderham St | L42: UFF000007273335 | M42: a13f1bd8-6858-5cf0-aa43-7d1f36cb2dc6 | O42: UFF000007273335 | P42: 2001908136 | Q42: UFB - SME Fibre 300 | R42: casual | T42: UFB - SME Fibre 300 | U42: 1 | V42: 46204 | W42: 46234 | X42: 46125 | Z42: NO LOGIN | AA42: Ritwik Kejriwal
A43: 141787 | B43: 46203 | C43: 6501155 | D43: secondary@circlenet.co.nz | E43: Legacy Network Static IP - Unlimited Data - apparelline-secondary@circlenet.co.nz (01/07/2026 - 31/07/2026) | F43: 15 | G43: 149 | H43: Unlimited Data | I43: Service Order | J43: Apparelline | L43: secondary@circlenet.co.nz | P43: 0 | Q43: Legacy Network Static IP | T43: Legacy Network Static IP | U43: 1 | V43: 46204 | W43: 46234 | X43: 0000-00-00
A44: 141787 | B44: 46203 | C44: 6501167 | D44: asphaltech@circlenet.co.nz | E44: Legacy Network Static IP - Unlimited Data - asphaltech@circlenet.co.nz (01/07/2026 - 31/07/2026) | F44: 15 | G44: 149 | H44: Unlimited Data | I44: Service Order | J44: Asphaltech | L44: asphaltech@circlenet.co.nz | P44: 0 | Q44: Legacy Network Static IP | T44: Legacy Network Static IP | U44: 1 | V44: 46204 | W44: 46234 | X44: 0000-00-00
...

Sheet By Customer
A1: Supplier Invoice 141787 – Charges by Customer
A2: Billing period 01/07/2026 – 31/07/2026. Supplier cost is pulled from the invoice sheet by customer + service; enter your on-charge in column F.
A4: Customer Name | B4: Service | C4: Invoice Lines | D4: Qty | E4: Supplier Cost ($) | F4: CIT charge to cus | G4: Margin ($)
A5: Alaska AKL - 4 Murdoch Road | B5: Static IP | C5: 1 | D5: 1 | E5: =SUMIFS('Invoice_141787_2026-06-30'!$F$2:$F$69,'Invoice_141787_2026-06-30'!$J$2:$J$69,$A5,'Invoice_141787_2026-06-30'!$T$2:$T$69,$B5) -> 5 | F5: 0 | G5: =IF($F5="","",$F5-$E5) -> -5
A6: Alaska AKL - 4 Murdoch Road | B6: UFB - Small Business Fibre 920 | C6: 1 | D6: 1 | E6: =SUMIFS('Invoice_141787_2026-06-30'!$F$2:$F$69,'Invoice_141787_2026-06-30'!$J$2:$J$69,$A6,'Invoice_141787_2026-06-30'!$T$2:$T$69,$B6) -> 100 | F6: 348 | G6: =IF($F6="","",$F6-$E6) -> 248
A7: Alaska AKL - 4 Murdoch Road – Total | C7: =SUM(C5:C6) -> 2 | D7: =SUM(D5:D6) -> 2 | E7: =SUM(E5:E6) -> 105 | F7: =SUM(F5:F6) -> 348 | G7: =SUM(G5:G6) -> 243
A9: Alaska CHCH - Unit 5/9 Sir Gil Simpson Dr | B9: Static IP | C9: 1 | D9: 1 | E9: =SUMIFS('Invoice_141787_2026-06-30'!$F$2:$F$69,'Invoice_141787_2026-06-30'!$J$2:$J$69,$A9,'Invoice_141787_2026-06-30'!$T$2:$T$69,$B9) -> 5 | F9: 0 | G9: =IF($F9="","",$F9-$E9) -> -5
A10: Alaska CHCH - Unit 5/9 Sir Gil Simpson Dr | B10: UFB - SME Fibre Max | C10: 1 | D10: 1 | E10: =SUMIFS('Invoice_141787_2026-06-30'!$F$2:$F$69,'Invoice_141787_2026-06-30'!$J$2:$J$69,$A10,'Invoice_141787_2026-06-30'!$T$2:$T$69,$B10) -> 110.5 | F10: 179 | G10: =IF($F10="","",$F10-$E10) -> 68.5
A11: Alaska CHCH - Unit 5/9 Sir Gil Simpson Dr – Total | C11: =SUM(C9:C10) -> 2 | D11: =SUM(D9:D10) -> 2 | E11: =SUM(E9:E10) -> 115.5 | F11: =SUM(F9:F10) -> 179 | G11: =SUM(G9:G10) -> 63.5
A13: Alaska TRG - 84 First Avenue | B13: Static IP | C13: 1 | D13: 1 | E13: =SUMIFS('Invoice_141787_2026-06-30'!$F$2:$F$69,'Invoice_141787_2026-06-30'!$J$2:$J$69,$A13,'Invoice_141787_2026-06-30'!$T$2:$T$69,$B13) -> 5 | F13: 0 | G13: =IF($F13="","",$F13-$E13) -> -5
A14: Alaska TRG - 84 First Avenue | B14: UFB - SME Fibre Max | C14: 1 | D14: 1 | E14: =SUMIFS('Invoice_141787_2026-06-30'!$F$2:$F$69,'Invoice_141787_2026-06-30'!$J$2:$J$69,$A14,'Invoice_141787_2026-06-30'!$T$2:$T$69,$B14) -> 118.5 | F14: 179 | G14: =IF($F14="","",$F14-$E14) -> 60.5
A15: Alaska TRG - 84 First Avenue – Total | C15: =SUM(C13:C14) -> 2 | D15: =SUM(D13:D14) -> 2 | E15: =SUM(E13:E14) -> 123.5 | F15: =SUM(F13:F14) -> 179 | G15: =SUM(G13:G14) -> 55.5
A17: Alaska WLG - 1/15 Glover Street | B17: Static IP | C17: 1 | D17: 1 | E17: =SUMIFS('Invoice_141787_2026-06-30'!$F$2:$F$69,'Invoice_141787_2026-06-30'!$J$2:$J$69,$A17,'Invoice_141787_2026-06-30'!$T$2:$T$69,$B17) -> 5 | F17: 0 | G17: =IF($F17="","",$F17-$E17) -> -5
A18: Alaska WLG - 1/15 Glover Street | B18: UFB - Small Business Fibre 920 | C18: 1 | D18: 1 | E18: =SUMIFS('Invoice_141787_2026-06-30'!$F$2:$F$69,'Invoice_141787_2026-06-30'!$J$2:$J$69,$A18,'Invoice_141787_2026-06-30'!$T$2:$T$69,$B18) -> 100 | F18: 179 | G18: =IF($F18="","",$F18-$E18) -> 79
A19: Alaska WLG - 1/15 Glover Street – Total | C19: =SUM(C17:C18) -> 2 | D19: =SUM(D17:D18) -> 2 | E19: =SUM(E17:E18) -> 105 | F19: =SUM(F17:F18) -> 179 | G19: =SUM(G17:G18) -> 74
A21: Apparelline | B21: Legacy Network Static IP | C21: 1 | D21: 1 | E21: =SUMIFS('Invoice_141787_2026-06-30'!$F$2:$F$69,'Invoice_141787_2026-06-30'!$J$2:$J$69,$A21,'Invoice_141787_2026-06-30'!$T$2:$T$69,$B21) -> 15 | F21: 114.4 | G21: =IF($F21="","",$F21-$E21) -> 99.4
A22: Apparelline | B22: Part Month Circuit Charges | C22: 1 | D22: 1 | E22: =SUMIFS('Invoice_141787_2026-06-30'!$F$2:$F$69,'Invoice_141787_2026-06-30'!$J$2:$J$69,$A22,'Invoice_141787_2026-06-30'!$T$2:$T$69,$B22) -> -5.45 | F22: 0 | G22: =IF($F22="","",$F22-$E22) -> 5.45
A23: Apparelline – Total | C23: =SUM(C21:C22) -> 2 | D23: =SUM(D21:D22) -> 2 | E23: =SUM(E21:E22) -> 9.55 | F23: =SUM(F21:F22) -> 114.4 | G23: =SUM(G21:G22) -> 104.85
A25: Asphaltech | B25: Legacy Network Static IP | C25: 1 | D25: 1 | E25: =SUMIFS('Invoice_141787_2026-06-30'!$F$2:$F$69,'Invoice_141787_2026-06-30'!$J$2:$J$69,$A25,'Invoice_141787_2026-06-30'!$T$2:$T$69,$B25) -> 15 | F25: 0 | G25: =IF($F25="","",$F25-$E25) -> -15
A26: Asphaltech | B26: UFB - Small Business Fibre 920 | C26: 1 | D26: 1 | E26: =SUMIFS('Invoice_141787_2026-06-30'!$F$2:$F$69,'Invoice_141787_2026-06-30'!$J$2:$J$69,$A26,'Invoice_141787_2026-06-30'!$T$2:$T$69,$B26) -> 100 | F26: 170.5 | G26: =IF($F26="","",$F26-$E26) -> 70.5
A27: Asphaltech – Total | C27: =SUM(C25:C26) -> 2 | D27: =SUM(D25:D26) -> 2 | E27: =SUM(E25:E26) -> 115 | F27: =SUM(F25:F26) -> 170.5 | G27: =SUM(G25:G26) -> 55.5
A29: Catch of the Day | B29: Static IP | C29: 2 | D29: 2 | E29: =SUMIFS('Invoice_141787_2026-06-30'!$F$2:$F$69,'Invoice_141787_2026-06-30'!$J$2:$J$69,$A29,'Invoice_141787_2026-06-30'!$T$2:$T$69,$B29) -> 10 | F29: 0 | G29: =IF($F29="","",$F29-$E29) -> -10
A30: Catch of the Day | B30: UFB - Small Business Fibre 500 | C30: 1 | D30: 1 | E30: =SUMIFS('Invoice_141787_2026-06-30'!$F$2:$F$69,'Invoice_141787_2026-06-30'!$J$2:$J$69,$A30,'Invoice_141787_2026-06-30'!$T$2:$T$69,$B30) -> 87 | F30: 132.5 | G30: =IF($F30="","",$F30-$E30) -> 45.5
A31: Catch of the Day | B31: UFB - Small Business Fibre 920 | C31: 1 | D31: 1 | E31: =SUMIFS('Invoice_141787_2026-06-30'!$F$2:$F$69,'Invoice_141787_2026-06-30'!$J$2:$J$69,$A31,'Invoice_141787_2026-06-30'!$T$2:$T$69,$B31) -> 100 | F31: 169.4 | G31: =IF($F31="","",$F31-$E31) -> 69.4
A32: Catch of the Day – Total | C32: =SUM(C29:C31) -> 4 | D32: =SUM(D29:D31) -> 4 | E32: =SUM(E29:E31) -> 197 | F32: =SUM(F29:F31) -> 301.9 | G32: =SUM(G29:G31) -> 104.9
A34: Circle IT | B34: Base Plan Difference Fees | C34: 1 | D34: 1 | E34: =SUMIFS('Invoice_141787_2026-06-30'!$F$2:$F$69,'Invoice_141787_2026-06-30'!$J$2:$J$69,$A34,'Invoice_141787_2026-06-30'!$T$2:$T$69,$B34) -> 21.98 | F34: 0 | G34: =IF($F34="","",$F34-$E34) -> -21.98
A35: Circle IT | B35: Legacy Network Static IP | C35: 1 | D35: 1 | E35: =SUMIFS('Invoice_141787_2026-06-30'!$F$2:$F$69,'Invoice_141787_2026-06-30'!$J$2:$J$69,$A35,'Invoice_141787_2026-06-30'!$T$2:$T$69,$B35) -> 15 | F35: 0 | G35: =IF($F35="","",$F35-$E35) -> -15
A36: Circle IT | B36: Toll Free Number | C36: 1 | D36: 1 | E36: =SUMIFS('Invoice_141787_2026-06-30'!$F$2:$F$69,'Invoice_141787_2026-06-30'!$J$2:$J$69,$A36,'Invoice_141787_2026-06-30'!$T$2:$T$69,$B36) -> 0 | F36: 0 | G36: =IF($F36="","",$F36-$E36) -> 0
A37: Circle IT | B37: UFB - Small Business Fibre 500 | C37: 1 | D37: 1 | E37: =SUMIFS('Invoice_141787_2026-06-30'!$F$2:$F$69,'Invoice_141787_2026-06-30'!$J$2:$J$69,$A37,'Invoice_141787_2026-06-30'!$T$2:$T$69,$B37) -> 87 | F37: 0 | G37: =IF($F37="","",$F37-$E37) -> -87
A38: Circle IT | B38: Voice Calling | C38: 2 | D38: 2 | E38: =SUMIFS('Invoice_141787_2026-06-30'!$F$2:$F$69,'Invoice_141787_2026-06-30'!$J$2:$J$69,$A38,'Invoice_141787_2026-06-30'!$T$2:$T$69,$B38) -> 2.74 | F38: 0 | G38: =IF($F38="","",$F38-$E38) -> -2.74
A39: Circle IT – Total | C39: =SUM(C34:C38) -> 6 | D39: =SUM(D34:D38) -> 6 | E39: =SUM(E34:E38) -> 126.72 | F39: =SUM(F34:F38) -> 0 | G39: =SUM(G34:G38) -> -126.72
A41: Darren Wong | B41: Legacy Network Static IP | C41: 1 | D41: 1 | E41: =SUMIFS('Invoice_141787_2026-06-30'!$F$2:$F$69,'Invoice_141787_2026-06-30'!$J$2:$J$69,$A41,'Invoice_141787_2026-06-30'!$T$2:$T$69,$B41) -> 15 | F41: 0 | G41: =IF($F41="","",$F41-$E41) -> -15 | H41: Lets get this cut
A42: Darren Wong | B42: UFB - Small Business Fibre 920 | C42: 1 | D42: 1 | E42: =SUMIFS('Invoice_141787_2026-06-30'!$F$2:$F$69,'Invoice_141787_2026-06-30'!$J$2:$J$69,$A42,'Invoice_141787_2026-06-30'!$T$2:$T$69,$B42) -> 100 | F42: 0 | G42: =IF($F42="","",$F42-$E42) -> -100 | H42: Lets get this cut
A43: Darren Wong – Total | C43: =SUM(C41:C42) -> 2 | D43: =SUM(D41:D42) -> 2 | E43: =SUM(E41:E42) -> 115 | F43: =SUM(F41:F42) -> 0 | G43: =SUM(G41:G42) -> -115
A45: Iosis Ltd | B45: Fax 2 Email | C45: 2 | D45: 2 | E45: =SUMIFS('Invoice_141787_2026-06-30'!$F$2:$F$69,'Invoice_141787_2026-06-30'!$J$2:$J$69,$A45,'Invoice_141787_2026-06-30'!$T$2:$T$69,$B45) -> 12 | F45: 15.62 | G45: =IF($F45="","",$F45-$E45) -> 3.62
A46: Iosis Ltd | B46: Static IP | C46: 1 | D46: 1 | E46: =SUMIFS('Invoice_141787_2026-06-30'!$F$2:$F$69,'Invoice_141787_2026-06-30'!$J$2:$J$69,$A46,'Invoice_141787_2026-06-30'!$T$2:$T$69,$B46) -> 5 | F46: 0 | G46: =IF($F46="","",$F46-$E46) -> -5
A47: Iosis Ltd | B47: UFB - Small Business Fibre 920 | C47: 1 | D47: 1 | E47: =SUMIFS('Invoice_141787_2026-06-30'!$F$2:$F$69,'Invoice_141787_2026-06-30'!$J$2:$J$69,$A47,'Invoice_141787_2026-06-30'!$T$2:$T$69,$B47) -> 100 | F47: 257.99 | G47: =IF($F47="","",$F47-$E47) -> 157.99
A48: Iosis Ltd | B48: Other Meraki charges that we didn't update | F48: =54+54+90+103.55+225+18+187.2 -> 731.75
A49: Iosis Ltd – Total | C49: =SUM(C45:C48) -> 4 | D49: =SUM(D45:D48) -> 4 | E49: =SUM(E45:E48) -> 117 | F49: =SUM(F45:F48) -> 1005.36 | G49: =SUM(G45:G48) -> 156.61
A51: Leukaemia Foundation | B51: Base Plan Difference Fees | C51: 1 | D51: 1 | E51: =SUMIFS('Invoice_141787_2026-06-30'!$F$2:$F$69,'Invoice_141787_2026-06-30'!$J$2:$J$69,$A51,'Invoice_141787_2026-06-30'!$T$2:$T$69,$B51) -> 24.2 | G51: =IF($F51="","",$F51-$E51)
...
